Workbook
Name anchor_tgt_columns_def: 'Source columns'!#REF!
Name anchor_tgt_columns_fk: 'Source columns'!$H$1
Name anchor_tgt_columns_note: 'Source columns'!$I$1
Name anchor_tgt_columns_null: 'Source columns'!$E$1
Name anchor_tgt_columns_pk: 'Source columns'!$G$1
Name anchor_tgt_columns_po: 'Source columns'!$F$1
Name anchor_tgt_columns_type: 'Source columns'!$D$1
Name lst_tgt_columns: 'Source columns'!$A:$I
Name anchor_tgt_tables_ntab: 'Target tables'!$E$1
Name anchor_tgt_tables_sa: 'Target tables'!$D$1
Name lst_tgt_tables: 'Target tables'!$A:$E
Name anchor_tgt_columns_def: 'Target columns'!$I$1
Name anchor_tgt_columns_fk: 'Target columns'!$H$1
Name anchor_tgt_columns_note: 'Target columns'!$J$1
Name anchor_tgt_columns_null: 'Target columns'!$E$1
Name anchor_tgt_columns_pk: 'Target columns'!$G$1
Name anchor_tgt_columns_po: 'Target columns'!$F$1
Name anchor_tgt_columns_type: 'Target columns'!$D$1
Name lst_tgt_columns: 'Target columns'!$A:$J
Name anchor_src_columns_note: #REF!
Name anchor_src_columns_null: #REF!
Name anchor_src_columns_pk: #REF!
Name anchor_src_columns_type: #REF!
Name anchor_tgt_columns_def: #REF!
Name anchor_tgt_columns_fk: #REF!
Name anchor_tgt_columns_note: #REF!
Name anchor_tgt_columns_null: #REF!
Name anchor_tgt_columns_pk: #REF!
Name anchor_tgt_columns_po: #REF!
Name anchor_tgt_columns_type: #REF!
Name anchor_tgt_tables_ntab: #REF!
Name anchor_tgt_tables_sa: #REF!
Name lst_src_columns: #REF!
Name lst_tgt_columns: #REF!
Name lst_tgt_tables: #REF!
Name anchor_src_columns_note: #REF!
Name anchor_src_columns_null: #REF!
Name anchor_src_columns_pk: #REF!
Name anchor_src_columns_type: #REF!
Name anchor_tgt_columns_def: #REF!
Name anchor_tgt_columns_fk: #REF!
Name anchor_tgt_columns_note: #REF!
Name anchor_tgt_columns_null: #REF!
Name anchor_tgt_columns_pk: #REF!
Name anchor_tgt_columns_po: #REF!
Name anchor_tgt_columns_type: #REF!
Name anchor_tgt_tables_ntab: #REF!
Name anchor_tgt_tables_sa: #REF!
Name d: '[1]Target columns'!$D$1
Name first_value: Глоссарий!$I$1:$I$3
Name lst_src_columns: #REF!
Name lst_tgt_columns: #REF!
Name lst_tgt_tables: #REF!
Name sff: '[1]Target columns'!$H$1

Sheet Список изменений
A1: Версия | B1: Дата | C1: Измененный объект | D1: Изменение | E1: Автор | F1: Комментарий

Sheet S2T
A2: № ПП | B2: Предметная область | C2: Описание целевой таблицы | D2: Таблица-приемник | E2: Тип данных поля приемника | F2: Первичный ключ? | G2: Внешний ключ? | H2: NULL? | I2: Описание поля приемника | J2: Поле приемника | K2: Таблица-источник | L2: Тип данных поля источника | M2: Описание поля источника | N2: Поле источника | O2: Трансформация поля источника | P2: Трансформации табличного уровня (SQL, пояснения) | Q2: Название N-таблицы | R2: Роль в истории | S2: СОД | T2: Кто менял | U2: Дата | V2: Комментарии
A3: 10 | D3: t_agr_rko | E3: =IFERROR(VLOOKUP($D3&$J3, target_columns[], 4, 0),"") -> date | F3: =IFERROR(VLOOKUP($D3&$J3, target_columns[], 7, 0),"") -> No | G3: =IFERROR(VLOOKUP($D3&$J3, target_columns[], 8, 0),"") -> No | H3: =IFERROR(VLOOKUP($D3&$J3, target_columns[], 5, 0),"") -> NULL | I3: =IFERROR(VLOOKUP($D3&$J3, target_columns[], 10, 0),"") -> Дата открытия | J3: open_dt | K3: b3060000410004_product | L3: =IFERROR(VLOOKUP(UPPER(K3&N3), source_columns[], 4,0),"") | M3: =IFERROR(VLOOKUP(UPPER(K3&N3), source_columns[], 7,0),"") | N3: begindate | Q3: ="n306000041_"&IFERROR(VLOOKUP(D3,target_tables[],5,0),"<not found>") -> n306000041_agr_rko | R3: - | S3: Снимок-снимок | T3: Сорокин М. Б. | U3: 45370
A4: 20 | D4: t_agr_rko | E4: =IFERROR(VLOOKUP($D4&$J4,target_columns[],4,0),"") -> date | F4: =IFERROR(VLOOKUP($D4&$J4,target_columns[],7,0),"") -> No | G4: =IFERROR(VLOOKUP($D4&$J4,target_columns[],8,0),"") -> No | H4: =IFERROR(VLOOKUP($D4&$J4,target_columns[],5,0),"") -> NULL | I4: =IFERROR(VLOOKUP($D4&$J4,target_columns[],10,0),"") -> Дата закрытия | J4: close_dt | K4: b3060000410004_product | L4: =IFERROR(VLOOKUP(UPPER(K4&N4),source_columns[],4,0),"") | M4: =IFERROR(VLOOKUP(UPPER(K4&N4),source_columns[],7,0),"") | N4: closedate | Q4: ="n306000041_"&IFERROR(VLOOKUP(D4,target_tables[],5,0),"<not found>") -> n306000041_agr_rko | R4: - | T4: Сорокин М. Б. | U4: 45370
A5: 30 | D5: t_agr_rko | E5: =IFERROR(VLOOKUP($D5&$J5,target_columns[],4,0),"") -> text | F5: =IFERROR(VLOOKUP($D5&$J5,target_columns[],7,0),"") -> No | G5: =IFERROR(VLOOKUP($D5&$J5,target_columns[],8,0),"") -> No | H5: =IFERROR(VLOOKUP($D5&$J5,target_columns[],5,0),"") -> NULL | I5: =IFERROR(VLOOKUP($D5&$J5,target_columns[],10,0),"") -> Номер договора | J5: agr_rko_num | K5: b3060000410004_product | L5: =IFERROR(VLOOKUP(UPPER(K5&N5),source_columns[],4,0),"") | M5: =IFERROR(VLOOKUP(UPPER(K5&N5),source_columns[],7,0),"") | N5: num | Q5: ="n306000041_"&IFERROR(VLOOKUP(D5,target_tables[],5,0),"<not found>") -> n306000041_agr_rko | R5: - | T5: Сорокин М. Б. | U5: 45370
A6: 40 | D6: t_agr_rko | E6: =IFERROR(VLOOKUP($D6&$J6,target_columns[],4,0),"") -> bigint | F6: =IFERROR(VLOOKUP($D6&$J6,target_columns[],7,0),"") -> No | G6: =IFERROR(VLOOKUP($D6&$J6,target_columns[],8,0),"") -> No | H6: =IFERROR(VLOOKUP($D6&$J6,target_columns[],5,0),"") -> NULL | I6: =IFERROR(VLOOKUP($D6&$J6,target_columns[],10,0),"") -> Уникальный идентификатор договора в системе-источнике | J6: host_agr_rko_id | K6: b3060000410004_product | L6: =IFERROR(VLOOKUP(UPPER(K6&N6),source_columns[],4,0),"") | M6: =IFERROR(VLOOKUP(UPPER(K6&N6),source_columns[],7,0),"") | N6: objectid | Q6: ="n306000041_"&IFERROR(VLOOKUP(D6,target_tables[],5,0),"<not found>") -> n306000041_agr_rko | R6: - | T6: Сорокин М. Б. | U6: 45370
A7: 50 | D7: t_agr_rko | E7: =IFERROR(VLOOKUP($D7&$J7,target_columns[],4,0),"") -> uuid | F7: =IFERROR(VLOOKUP($D7&$J7,target_columns[],7,0),"") -> No | G7: =IFERROR(VLOOKUP($D7&$J7,target_columns[],8,0),"") -> Yes | H7: =IFERROR(VLOOKUP($D7&$J7,target_columns[],5,0),"") -> NULL | I7: =IFERROR(VLOOKUP($D7&$J7,target_columns[],10,0),"") -> Валюта договора | J7: crncy_id | K7: b3060000410004_product | L7: =IFERROR(VLOOKUP(UPPER(K7&N7),source_columns[],4,0),"") | M7: =IFERROR(VLOOKUP(UPPER(K7&N7),source_columns[],7,0),"") | N7: currency_short_foreign_key_uid | Q7: ="n306000041_"&IFERROR(VLOOKUP(D7,target_tables[],5,0),"<not found>") -> n306000041_agr_rko | R7: - | T7: Сорокин М. Б. | U7: 45370
A8: 60 | D8: t_agr_rko | E8: =IFERROR(VLOOKUP($D8&$J8,target_columns[],4,0),"") -> uuid | F8: =IFERROR(VLOOKUP($D8&$J8,target_columns[],7,0),"") -> No | G8: =IFERROR(VLOOKUP($D8&$J8,target_columns[],8,0),"") -> Yes | H8: =IFERROR(VLOOKUP($D8&$J8,target_columns[],5,0),"") -> NULL | I8: =IFERROR(VLOOKUP($D8&$J8,target_columns[],10,0),"") -> Целевое назначение договора (счета) | J8: rko_purpose_type_id | K8: b3060000410004_product | L8: =IFERROR(VLOOKUP(UPPER(K8&N8),source_columns[],4,0),"") | M8: =IFERROR(VLOOKUP(UPPER(K8&N8),source_columns[],7,0),"") | N8: Target_short_foreign_key_uid | Q8: ="n306000041_"&IFERROR(VLOOKUP(D8,target_tables[],5,0),"<not found>") -> n306000041_agr_rko | R8: - | T8: Сорокин М. Б. | U8: 45370
A9: 70 | D9: t_agr_rko | E9: =IFERROR(VLOOKUP($D9&$J9,target_columns[],4,0),"") -> uuid | F9: =IFERROR(VLOOKUP($D9&$J9,target_columns[],7,0),"") -> Yes | G9: =IFERROR(VLOOKUP($D9&$J9,target_columns[],8,0),"") -> No | H9: =IFERROR(VLOOKUP($D9&$J9,target_columns[],5,0),"") -> NOT NULL | I9: =IFERROR(VLOOKUP($D9&$J9,target_columns[],10,0),"") -> Уникальный идентификатор договора | J9: agr_rko_id | K9: b3060000410004_product | L9: =IFERROR(VLOOKUP(UPPER(K9&N9),source_columns[],4,0),"") | M9: =IFERROR(VLOOKUP(UPPER(K9&N9),source_columns[],7,0),"") | N9: ObjectID_uid | Q9: ="n306000041_"&IFERROR(VLOOKUP(D9,target_tables[],5,0),"<not found>") -> n306000041_agr_rko | R9: Ключ | T9: Сорокин М. Б. | U9: 45370
A10: 100 | D10: t_agr_rko_cust | E10: =IFERROR(VLOOKUP($D10&$J10, target_columns[], 4, 0),"") -> uuid | F10: =IFERROR(VLOOKUP($D10&$J10, target_columns[], 7, 0),"") -> Yes | G10: =IFERROR(VLOOKUP($D10&$J10, target_columns[], 8, 0),"") -> Yes | H10: =IFERROR(VLOOKUP($D10&$J10, target_columns[], 5, 0),"") -> NOT NULL | I10: =IFERROR(VLOOKUP($D10&$J10, target_columns[], 10, 0),"") -> Уникальный идентификатор договора | J10: agr_rko_id | K10: b3060000410004_product | L10: =IFERROR(VLOOKUP(UPPER(K10&N10), source_columns[], 4,0),"") | M10: =IFERROR(VLOOKUP(UPPER(K10&N10), source_columns[], 7,0),"") | N10: ObjectID_uid | Q10: ="n306000041_"&IFERROR(VLOOKUP(D10,target_tables[],5,0),"<not found>") -> n306000041_agr_rko_cust | R10: Ключ | S10: Снимок-история | T10: Сорокин М. Б. | U10: 45370
A11: 110 | D11: t_agr_rko_cust | E11: =IFERROR(VLOOKUP($D11&$J11,target_columns[],4,0),"") -> date | F11: =IFERROR(VLOOKUP($D11&$J11,target_columns[],7,0),"") -> Yes | G11: =IFERROR(VLOOKUP($D11&$J11,target_columns[],8,0),"") -> No | H11: =IFERROR(VLOOKUP($D11&$J11,target_columns[],5,0),"") -> NULL | I11: =IFERROR(VLOOKUP($D11&$J11,target_columns[],10,0),"") -> Дата начала действия связи | J11: start_dt | K11: ETL | L11: =IFERROR(VLOOKUP(UPPER(K11&N11),source_columns[],4,0),"") | M11: =IFERROR(VLOOKUP(UPPER(K11&N11),source_columns[],7,0),"") | N11: ctl_validfrom | O11: Заполняется в соответствии с СОД Снимок-История. Первая запись в истории должна иметь значение MinDate | Q11: ="n306000041_"&IFERROR(VLOOKUP(D11,target_tables[],5,0),"<not found>") -> n306000041_agr_rko_cust | R11: Начало | T11: Сорокин М. Б. | U11: 45370
A12: 120 | D12: t_agr_rko_cust | E12: =IFERROR(VLOOKUP($D12&$J12,target_columns[],4,0),"") -> date | F12: =IFERROR(VLOOKUP($D12&$J12,target_columns[],7,0),"") -> No | G12: =IFERROR(VLOOKUP($D12&$J12,target_columns[],8,0),"") -> No | H12: =IFERROR(VLOOKUP($D12&$J12,target_columns[],5,0),"") -> NULL | I12: =IFERROR(VLOOKUP($D12&$J12,target_columns[],10,0),"") -> Дата окончания действия связи | J12: end_dt | K12: ETL | L12: =IFERROR(VLOOKUP(UPPER(K12&N12),source_columns[],4,0),"") | M12: =IFERROR(VLOOKUP(UPPER(K12&N12),source_columns[],7,0),"") | N12: ETL | O12: Заполняется в соответствии с СОД Снимок-История | Q12: ="n306000041_"&IFERROR(VLOOKUP(D12,target_tables[],5,0),"<not found>") -> n306000041_agr_rko_cust | R12: Конец | T12: Сорокин М. Б. | U12: 45370
A13: 130 | D13: t_agr_rko_cust | E13: =IFERROR(VLOOKUP($D13&$J13,target_columns[],4,0),"") -> uuid | F13: =IFERROR(VLOOKUP($D13&$J13,target_columns[],7,0),"") -> No | G13: =IFERROR(VLOOKUP($D13&$J13,target_columns[],8,0),"") -> Yes | H13: =IFERROR(VLOOKUP($D13&$J13,target_columns[],5,0),"") -> NULL | I13: =IFERROR(VLOOKUP($D13&$J13,target_columns[],10,0),"") -> Клиент по договору | J13: cust_id | K13: b3060000410004_product | L13: =IFERROR(VLOOKUP(UPPER(K13&N13),source_columns[],4,0),"") | M13: =IFERROR(VLOOKUP(UPPER(K13&N13),source_columns[],7,0),"") | N13: ownerEpkId_entityId_uid | Q13: ="n306000041_"&IFERROR(VLOOKUP(D13,target_tables[],5,0),"<not found>") -> n306000041_agr_rko_cust | R13: - | T13: Сорокин М. Б. | U13: 45370
A14: 180 | D14: t_agr_rko_int_org | E14: =IFERROR(VLOOKUP($D14&$J14,target_columns[],4,0),"") -> uuid | F14: =IFERROR(VLOOKUP($D14&$J14,target_columns[],7,0),"") -> Yes | G14: =IFERROR(VLOOKUP($D14&$J14,target_columns[],8,0),"") -> Yes | H14: =IFERROR(VLOOKUP($D14&$J14,target_columns[],5,0),"") -> NOT NULL | I14: =IFERROR(VLOOKUP($D14&$J14,target_columns[],10,0),"") -> Уникальный идентификатор договора | J14: agr_rko_id | K14: b3060000410004_product | L14: =IFERROR(VLOOKUP(UPPER(K14&N14),source_columns[],4,0),"") | M14: =IFERROR(VLOOKUP(UPPER(K14&N14),source_columns[],7,0),"") | N14: ObjectID_uid | Q14: ="n306000041_"&IFERROR(VLOOKUP(D14,target_tables[],5,0),"<not found>") -> n306000041_agr_rko_int_org | R14: Ключ | S14: Снимок-история | T14: Сорокин М. Б. | U14: 45370
A15: 190 | D15: t_agr_rko_int_org | E15: =IFERROR(VLOOKUP($D15&$J15,target_columns[],4,0),"") -> date | F15: =IFERROR(VLOOKUP($D15&$J15,target_columns[],7,0),"") -> Yes | G15: =IFERROR(VLOOKUP($D15&$J15,target_columns[],8,0),"") -> No | H15: =IFERROR(VLOOKUP($D15&$J15,target_columns[],5,0),"") -> NULL | I15: =IFERROR(VLOOKUP($D15&$J15,target_columns[],10,0),"") -> Дата начала действия связи | J15: start_dt | K15: ETL | L15: =IFERROR(VLOOKUP(UPPER(K15&N15),source_columns[],4,0),"") | M15: =IFERROR(VLOOKUP(UPPER(K15&N15),source_columns[],7,0),"") | N15: ctl_validfrom | O15: Заполняется в соответствии с СОД Снимок-История. Первая запись в истории должна иметь значение MinDate | Q15: ="n306000041_"&IFERROR(VLOOKUP(D15,target_tables[],5,0),"<not found>") -> n306000041_agr_rko_int_org | R15: Начало | T15: Сорокин М. Б. | U15: 45370
A16: 200 | D16: t_agr_rko_int_org | E16: =IFERROR(VLOOKUP($D16&$J16,target_columns[],4,0),"") -> date | F16: =IFERROR(VLOOKUP($D16&$J16,target_columns[],7,0),"") -> No | G16: =IFERROR(VLOOKUP($D16&$J16,target_columns[],8,0),"") -> No | H16: =IFERROR(VLOOKUP($D16&$J16,target_columns[],5,0),"") -> NULL | I16: =IFERROR(VLOOKUP($D16&$J16,target_columns[],10,0),"") -> Дата окончания действия связи | J16: end_dt | K16: ETL | L16: =IFERROR(VLOOKUP(UPPER(K16&N16),source_columns[],4,0),"") | M16: =IFERROR(VLOOKUP(UPPER(K16&N16),source_columns[],7,0),"") | N16: ETL | O16: Заполняется в соответствии с СОД Снимок-История | Q16: ="n306000041_"&IFERROR(VLOOKUP(D16,target_tables[],5,0),"<not found>") -> n306000041_agr_rko_int_org | R16: Конец | T16: Сорокин М. Б. | U16: 45370
A17: 210 | D17: t_agr_rko_int_org | E17: =IFERROR(VLOOKUP($D17&$J17,target_columns[],4,0),"") -> uuid | F17: =IFERROR(VLOOKUP($D17&$J17,target_columns[],7,0),"") -> No | G17: =IFERROR(VLOOKUP($D17&$J17,target_columns[],8,0),"") -> Yes | H17: =IFERROR(VLOOKUP($D17&$J17,target_columns[],5,0),"") -> NULL | I17: =IFERROR(VLOOKUP($D17&$J17,target_columns[],10,0),"") -> Подразделение сопровождения договора | J17: int_org_id | K17: b3060000410004_product | L17: =IFERROR(VLOOKUP(UPPER(K17&N17),source_columns[],4,0),"") | M17: =IFERROR(VLOOKUP(UPPER(K17&N17),source_columns[],7,0),"") | N17: divisionId_uid | Q17: ="n306000041_"&IFERROR(VLOOKUP(D17,target_tables[],5,0),"<not found>") -> n306000041_agr_rko_int_org | R17: - | T17: Сорокин М. Б. | U17: 45370
A18: 260 | D18: t_agr_rko_stts | E18: =IFERROR(VLOOKUP($D18&$J18,target_columns[],4,0),"") -> uuid | F18: =IFERROR(VLOOKUP($D18&$J18,target_columns[],7,0),"") -> Yes | G18: =IFERROR(VLOOKUP($D18&$J18,target_columns[],8,0),"") -> Yes | H18: =IFERROR(VLOOKUP($D18&$J18,target_columns[],5,0),"") -> NOT NULL | I18: =IFERROR(VLOOKUP($D18&$J18,target_columns[],10,0),"") -> Уникальный идентификатор договора | J18: agr_rko_id | K18: b3060000410004_product | L18: =IFERROR(VLOOKUP(UPPER(K18&N18),source_columns[],4,0),"") | M18: =IFERROR(VLOOKUP(UPPER(K18&N18),source_columns[],7,0),"") | N18: ObjectID_uid | Q18: ="n306000041_"&IFERROR(VLOOKUP(D18,target_tables[],5,0),"<not found>") -> n306000041_agr_rko_stts | R18: Ключ | S18: Снимок-история | T18: Сорокин М. Б. | U18: 45370
A19: 270 | D19: t_agr_rko_stts | E19: =IFERROR(VLOOKUP($D19&$J19,target_columns[],4,0),"") -> date | F19: =IFERROR(VLOOKUP($D19&$J19,target_columns[],7,0),"") -> Yes | G19: =IFERROR(VLOOKUP($D19&$J19,target_columns[],8,0),"") -> No | H19: =IFERROR(VLOOKUP($D19&$J19,target_columns[],5,0),"") -> NULL | I19: =IFERROR(VLOOKUP($D19&$J19,target_columns[],10,0),"") -> Дата начала действия связи | J19: start_dt | K19: ETL | L19: =IFERROR(VLOOKUP(UPPER(K19&N19),source_columns[],4,0),"") | M19: =IFERROR(VLOOKUP(UPPER(K19&N19),source_columns[],7,0),"") | N19: ctl_validfrom | O19: Заполняется в соответствии с СОД Снимок-История. Первая запись в истории должна иметь значение MinDate | Q19: ="n306000041_"&IFERROR(VLOOKUP(D19,target_tables[],5,0),"<not found>") -> n306000041_agr_rko_stts | R19: Начало | T19: Сорокин М. Б. | U19: 45370
A20: 280 | D20: t_agr_rko_stts | E20: =IFERROR(VLOOKUP($D20&$J20,target_columns[],4,0),"") -> date | F20: =IFERROR(VLOOKUP($D20&$J20,target_columns[],7,0),"") -> No | G20: =IFERROR(VLOOKUP($D20&$J20,target_columns[],8,0),"") -> No | H20: =IFERROR(VLOOKUP($D20&$J20,target_columns[],5,0),"") -> NULL | I20: =IFERROR(VLOOKUP($D20&$J20,target_columns[],10,0),"") -> Дата окончания действия связи | J20: end_dt | K20: ETL | L20: =IFERROR(VLOOKUP(UPPER(K20&N20),source_columns[],4,0),"") | M20: =IFERROR(VLOOKUP(UPPER(K20&N20),source_columns[],7,0),"") | N20: ETL | O20: Заполняется в соответствии с СОД Снимок-История | Q20: ="n306000041_"&IFERROR(VLOOKUP(D20,target_tables[],5,0),"<not found>") -> n306000041_agr_rko_stts | R20: Конец | T20: Сорокин М. Б. | U20: 45370
A21: 290 | D21: t_agr_rko_stts | E21: =IFERROR(VLOOKUP($D21&$J21,target_columns[],4,0),"") -> uuid | F21: =IFERROR(VLOOKUP($D21&$J21,target_columns[],7,0),"") -> No | G21: =IFERROR(VLOOKUP($D21&$J21,target_columns[],8,0),"") -> Yes | H21: =IFERROR(VLOOKUP($D21&$J21,target_columns[],5,0),"") -> NULL | I21: =IFERROR(VLOOKUP($D21&$J21,target_columns[],10,0),"") -> Статус договора | J21: agr_rko_stts_type_id | K21: b3060000410004_product | L21: =IFERROR(VLOOKUP(UPPER(K21&N21),source_columns[],4,0),"") | M21: =IFERROR(VLOOKUP(UPPER(K21&N21),source_columns[],7,0),"") | N21: statusCode_short_foreign_key_uid | Q21: ="n306000041_"&IFERROR(VLOOKUP(D21,target_tables[],5,0),"<not found>") -> n306000041_agr_rko_stts | R21: - | T21: Сорокин М. Б. | U21: 45370
A22: 300 | D22: t_registry | E22: =IFERROR(VLOOKUP($D22&$J22,target_columns[],4,0),"") -> uuid | F22: =IFERROR(VLOOKUP($D22&$J22,target_columns[],7,0),"") -> Yes | G22: =IFERROR(VLOOKUP($D22&$J22,target_columns[],8,0),"") -> No | H22: =IFERROR(VLOOKUP($D22&$J22,target_columns[],5,0),"") -> NOT NULL | I22: =IFERROR(VLOOKUP($D22&$J22,target_columns[],10,0),"") -> Уникальный идентификатор регистра | J22: registry_id | K22: b3060000410001_register | L22: =IFERROR(VLOOKUP(UPPER(K22&N22),source_columns[],4,0),"") | M22: =IFERROR(VLOOKUP(UPPER(K22&N22),source_columns[],7,0),"") | N22: Objectid_uid | Q22: ="n306000041_"&IFERROR(VLOOKUP(D22,target_tables[],5,0),"<not found>") -> n306000041_registry | R22: Ключ | S22: Снимок-снимок с накоплением | T22: Сорокин М. Б. | U22: 45370
A23: 310 | D23: t_registry | E23: =IFERROR(VLOOKUP($D23&$J23,target_columns[],4,0),"") -> date | F23: =IFERROR(VLOOKUP($D23&$J23,target_columns[],7,0),"") -> No | G23: =IFERROR(VLOOKUP($D23&$J23,target_columns[],8,0),"") -> No | H23: =IFERROR(VLOOKUP($D23&$J23,target_columns[],5,0),"") -> NULL | I23: =IFERROR(VLOOKUP($D23&$J23,target_columns[],10,0),"") -> Дата опердня, в которую был открыт регистр | J23: start_dt | K23: b3060000410001_register | L23: =IFERROR(VLOOKUP(UPPER(K23&N23),source_columns[],4,0),"") -> timestamp | M23: =IFERROR(VLOOKUP(UPPER(K23&N23),source_columns[],7,0),"") -> Дата открытия | N23: begindate | Q23: ="n306000041_"&IFERROR(VLOOKUP(D23,target_tables[],5,0),"<not found>") -> n306000041_registry | R23: - | T23: Сорокин М. Б. | U23: 45370
A24: 320 | D24: t_registry | E24: =IFERROR(VLOOKUP($D24&$J24,target_columns[],4,0),"") -> date | F24: =IFERROR(VLOOKUP($D24&$J24,target_columns[],7,0),"") -> No | G24: =IFERROR(VLOOKUP($D24&$J24,target_columns[],8,0),"") -> No | H24: =IFERROR(VLOOKUP($D24&$J24,target_columns[],5,0),"") -> NULL | I24: =IFERROR(VLOOKUP($D24&$J24,target_columns[],10,0),"") -> Дата опердня, в которую был закрыт регистр | J24: end_dt | K24: b3060000410001_register | L24: =IFERROR(VLOOKUP(UPPER(K24&N24),source_columns[],4,0),"") | M24: =IFERROR(VLOOKUP(UPPER(K24&N24),source_columns[],7,0),"") | N24: enddate | Q24: ="n306000041_"&IFERROR(VLOOKUP(D24,target_tables[],5,0),"<not found>") -> n306000041_registry | R24: - | T24: Сорокин М. Б. | U24: 45370
A25: 330 | D25: t_registry | E25: =IFERROR(VLOOKUP($D25&$J25,target_columns[],4,0),"") -> uuid | F25: =IFERROR(VLOOKUP($D25&$J25,target_columns[],7,0),"") -> No | G25: =IFERROR(VLOOKUP($D25&$J25,target_columns[],8,0),"") -> Yes | H25: =IFERROR(VLOOKUP($D25&$J25,target_columns[],5,0),"") -> NULL | I25: =IFERROR(VLOOKUP($D25&$J25,target_columns[],10,0),"") -> Договор | J25: agr_id | K25: b3060000410001_register | L25: =IFERROR(VLOOKUP(UPPER(K25&N25),source_columns[],4,0),"") | M25: =IFERROR(VLOOKUP(UPPER(K25&N25),source_columns[],7,0),"") | N25: product_short_foreign_key_uid | Q25: ="n306000041_"&IFERROR(VLOOKUP(D25,target_tables[],5,0),"<not found>") -> n306000041_registry | R25: - | T25: Сорокин М. Б. | U25: 45370
A26: 340 | D26: t_registry | E26: =IFERROR(VLOOKUP($D26&$J26,target_columns[],4,0),"") -> text | F26: =IFERROR(VLOOKUP($D26&$J26,target_columns[],7,0),"") -> No | G26: =IFERROR(VLOOKUP($D26&$J26,target_columns[],8,0),"") -> No | H26: =IFERROR(VLOOKUP($D26&$J26,target_columns[],5,0),"") -> NULL | I26: =IFERROR(VLOOKUP($D26&$J26,target_columns[],10,0),"") -> Лицевой счет | J26: coa_num | K26: b3060000410001_register | L26: =IFERROR(VLOOKUP(UPPER(K26&N26),source_columns[],4,0),"") -> text | M26: =IFERROR(VLOOKUP(UPPER(K26&N26),source_columns[],7,0),"") -> Номер счета | N26: number | Q26: ="n306000041_"&IFERROR(VLOOKUP(D26,target_tables[],5,0),"<not found>") -> n306000041_registry | R26: - | T26: Сорокин М. Б. | U26: 45370
A27: 350 | D27: t_registry | E27: =IFERROR(VLOOKUP($D27&$J27,target_columns[],4,0),"") -> uuid | F27: =IFERROR(VLOOKUP($D27&$J27,target_columns[],7,0),"") -> No | G27: =IFERROR(VLOOKUP($D27&$J27,target_columns[],8,0),"") -> No | H27: =IFERROR(VLOOKUP($D27&$J27,target_columns[],5,0),"") -> NULL | I27: =IFERROR(VLOOKUP($D27&$J27,target_columns[],10,0),"") -> Уникальный идентификатор валюты | J27: crncy_id | K27: b3060000410001_register | L27: =IFERROR(VLOOKUP(UPPER(K27&N27),source_columns[],4,0),"") | M27: =IFERROR(VLOOKUP(UPPER(K27&N27),source_columns[],7,0),"") | N27: currency_short_foreign_key_uid | Q27: ="n306000041_"&IFERROR(VLOOKUP(D27,target_tables[],5,0),"<not found>") -> n306000041_registry | R27: - | T27: Сорокин М. Б. | U27: 45370
A28: 360 | D28: t_registry | E28: =IFERROR(VLOOKUP($D28&$J28,target_columns[],4,0),"") -> bigint | F28: =IFERROR(VLOOKUP($D28&$J28,target_columns[],7,0),"") -> No | G28: =IFERROR(VLOOKUP($D28&$J28,target_columns[],8,0),"") -> No | H28: =IFERROR(VLOOKUP($D28&$J28,target_columns[],5,0),"") -> NULL | I28: =IFERROR(VLOOKUP($D28&$J28,target_columns[],10,0),"") -> Уникальный идентификатор регистра в источнике | J28: host_registry_id | K28: b3060000410001_register | L28: =IFERROR(VLOOKUP(UPPER(K28&N28),source_columns[],4,0),"") -> bigint | M28: =IFERROR(VLOOKUP(UPPER(K28&N28),source_columns[],7,0),"") -> Уникальный идентификатор | N28: objectID | Q28: ="n306000041_"&IFERROR(VLOOKUP(D28,target_tables[],5,0),"<not found>") -> n306000041_registry | R28: - | T28: Сорокин М. Б. | U28: 45370
A29: 370 | D29: t_registry | E29: =IFERROR(VLOOKUP($D29&$J29,target_columns[],4,0),"") -> uuid | F29: =IFERROR(VLOOKUP($D29&$J29,target_columns[],7,0),"") -> No | G29: =IFERROR(VLOOKUP($D29&$J29,target_columns[],8,0),"") -> Yes | H29: =IFERROR(VLOOKUP($D29&$J29,target_columns[],5,0),"") -> NULL | I29: =IFERROR(VLOOKUP($D29&$J29,target_columns[],10,0),"") -> Тип регистра | J29: registry_type_id | K29: b3060000410001_register | L29: =IFERROR(VLOOKUP(UPPER(K29&N29),source_columns[],4,0),"") | M29: =IFERROR(VLOOKUP(UPPER(K29&N29),source_columns[],7,0),"") | N29: registerType_short_foreign_key_uid | Q29: ="n306000041_"&IFERROR(VLOOKUP(D29,target_tables[],5,0),"<not found>") -> n306000041_registry | R29: - | T29: Сорокин М. Б. | U29: 45370
A30: 380 | D30: T_REGISTRY_STTS | E30: =IFERROR(VLOOKUP($D30&$J30,target_columns[],4,0),"") | F30: =IFERROR(VLOOKUP($D30&$J30,target_columns[],7,0),"") | G30: =IFERROR(VLOOKUP($D30&$J30,target_columns[],8,0),"") | H30: =IFERROR(VLOOKUP($D30&$J30,target_columns[],5,0),"") | I30: =IFERROR(VLOOKUP($D30&$J30,target_columns[],10,0),"") | J30: registry_id | K30: b3060000410001_register | L30: =IFERROR(VLOOKUP(UPPER(K30&N30),source_columns[],4,0),"") | M30: =IFERROR(VLOOKUP(UPPER(K30&N30),source_columns[],7,0),"") | N30: ObjectID_uid | Q30: ="n306000041_"&IFERROR(VLOOKUP(D30,target_tables[],5,0),"<not found>") -> n306000041_REGISTRY_STTS | R30: Ключ | S30: Снимок-история | T30: Сорокин М. Б. | U30: 45370
A31: 390 | D31: T_REGISTRY_STTS | E31: =IFERROR(VLOOKUP($D31&$J31,target_columns[],4,0),"") | F31: =IFERROR(VLOOKUP($D31&$J31,target_columns[],7,0),"") | G31: =IFERROR(VLOOKUP($D31&$J31,target_columns[],8,0),"") | H31: =IFERROR(VLOOKUP($D31&$J31,target_columns[],5,0),"") | I31: =IFERROR(VLOOKUP($D31&$J31,target_columns[],10,0),"") | J31: start_dt | K31: ETL | L31: =IFERROR(VLOOKUP(UPPER(K31&N31),source_columns[],4,0),"") | M31: =IFERROR(VLOOKUP(UPPER(K31&N31),source_columns[],7,0),"") | N31: ctl_validfrom | O31: Заполняется в соответствии с СОД Снимок-История. Первая запись в истории должна иметь значение MinDate | Q31: ="n306000041_"&IFERROR(VLOOKUP(D31,target_tables[],5,0),"<not found>") -> n306000041_REGISTRY_STTS | R31: Начало | T31: Сорокин М. Б. | U31: 45370
A32: 400 | D32: T_REGISTRY_STTS | E32: =IFERROR(VLOOKUP($D32&$J32,target_columns[],4,0),"") | F32: =IFERROR(VLOOKUP($D32&$J32,target_columns[],7,0),"") | G32: =IFERROR(VLOOKUP($D32&$J32,target_columns[],8,0),"") | H32: =IFERROR(VLOOKUP($D32&$J32,target_columns[],5,0),"") | I32: =IFERROR(VLOOKUP($D32&$J32,target_columns[],10,0),"") | J32: end_dt | K32: ETL | L32: =IFERROR(VLOOKUP(UPPER(K32&N32),source_columns[],4,0),"") | M32: =IFERROR(VLOOKUP(UPPER(K32&N32),source_columns[],7,0),"") | N32: ETL | O32: Заполняется в соответствии с СОД Снимок-История | Q32: ="n306000041_"&IFERROR(VLOOKUP(D32,target_tables[],5,0),"<not found>") -> n306000041_REGISTRY_STTS | R32: Конец | T32: Сорокин М. Б. | U32: 45370
A33: 410 | D33: T_REGISTRY_STTS | E33: =IFERROR(VLOOKUP($D33&$J33,target_columns[],4,0),"") -> UUID | F33: =IFERROR(VLOOKUP($D33&$J33,target_columns[],7,0),"") -> No | G33: =IFERROR(VLOOKUP($D33&$J33,target_columns[],8,0),"") -> Yes | H33: =IFERROR(VLOOKUP($D33&$J33,target_columns[],5,0),"") -> NULL | I33: =IFERROR(VLOOKUP($D33&$J33,target_columns[],10,0),"") -> Идентификатор типа статуса регистра | J33: REGISTRY_STTS_TYPE_ID | K33: b3060000410001_register | L33: =IFERROR(VLOOKUP(UPPER(K33&N33),source_columns[],4,0),"") | M33: =IFERROR(VLOOKUP(UPPER(K33&N33),source_columns[],7,0),"") | N33: status_short_foreign_key_uid | Q33: ="n306000041_"&IFERROR(VLOOKUP(D33,target_tables[],5,0),"<not found>") -> n306000041_REGISTRY_STTS | R33: - | T33: Сорокин М. Б. | U33: 45370
A34: 420 | D34: t_registry_type | E34: =IFERROR(VLOOKUP($D34&$J34,target_columns[],4,0),"") -> uuid | F34: =IFERROR(VLOOKUP($D34&$J34,target_columns[],7,0),"") -> Yes | G34: =IFERROR(VLOOKUP($D34&$J34,target_columns[],8,0),"") -> No | H34: =IFERROR(VLOOKUP($D34&$J34,target_columns[],5,0),"") -> NOT NULL | I34: =IFERROR(VLOOKUP($D34&$J34,target_columns[],10,0),"") -> Уникальный идентификатор типа регистра | J34: registry_type_id | K34: b3060000410006_registertype | L34: =IFERROR(VLOOKUP(UPPER(K34&N34),source_columns[],4,0),"") | M34: =IFERROR(VLOOKUP(UPPER(K34&N34),source_columns[],7,0),"") | N34: ObjectID_uid | Q34: ="n306000041_"&IFERROR(VLOOKUP(D34,target_tables[],5,0),"<not found>") -> n306000041_registry_type | R34: Ключ | S34: Снимок-снимок с накоплением | T34: Сорокин М. Б. | U34: 45370
A35: 430 | D35: t_registry_type | E35: =IFERROR(VLOOKUP($D35&$J35,target_columns[],4,0),"") -> text | F35: =IFERROR(VLOOKUP($D35&$J35,target_columns[],7,0),"") -> No | G35: =IFERROR(VLOOKUP($D35&$J35,target_columns[],8,0),"") -> No | H35: =IFERROR(VLOOKUP($D35&$J35,target_columns[],5,0),"") -> NULL | I35: =IFERROR(VLOOKUP($D35&$J35,target_columns[],10,0),"") -> Наименование типа регистра | J35: registry_type_name | K35: b3060000410006_registertype | L35: =IFERROR(VLOOKUP(UPPER(K35&N35),source_columns[],4,0),"") | M35: =IFERROR(VLOOKUP(UPPER(K35&N35),source_columns[],7,0),"") | N35: name | Q35: ="n306000041_"&IFERROR(VLOOKUP(D35,target_tables[],5,0),"<not found>") -> n306000041_registry_type | R35: - | T35: Сорокин М. Б. | U35: 45370
A36: 440 | D36: t_registry_type | E36: =IFERROR(VLOOKUP($D36&$J36,target_columns[],4,0),"") -> text | F36: =IFERROR(VLOOKUP($D36&$J36,target_columns[],7,0),"") -> No | G36: =IFERROR(VLOOKUP($D36&$J36,target_columns[],8,0),"") -> No | H36: =IFERROR(VLOOKUP($D36&$J36,target_columns[],5,0),"") -> NULL | I36: =IFERROR(VLOOKUP($D36&$J36,target_columns[],10,0),"") -> Код регистра | J36: registry_type_cd | K36: b3060000410006_registertype | L36: =IFERROR(VLOOKUP(UPPER(K36&N36),source_columns[],4,0),"") | M36: =IFERROR(VLOOKUP(UPPER(K36&N36),source_columns[],7,0),"") | N36: objectID | Q36: ="n306000041_"&IFERROR(VLOOKUP(D36,target_tables[],5,0),"<not found>") -> n306000041_registry_type | R36: - | T36: Сорокин М. Б. | U36: 45370
A37: 450 | D37: t_appl | E37: =IFERROR(VLOOKUP($D37&$J37,target_columns[],4,0),"") -> uuid | F37: =IFERROR(VLOOKUP($D37&$J37,target_columns[],7,0),"") -> Yes | G37: =IFERROR(VLOOKUP($D37&$J37,target_columns[],8,0),"") -> No | H37: =IFERROR(VLOOKUP($D37&$J37,target_columns[],5,0),"") -> NOT NULL | I37: =IFERROR(VLOOKUP($D37&$J37,target_columns[],10,0),"") -> Идентификатор заявки | J37: appl_id | K37: b3060000410002_createrkoext | L37: =IFERROR(VLOOKUP(UPPER(K37&N37),source_columns[],4,0),"") | M37: =IFERROR(VLOOKUP(UPPER(K37&N37),source_columns[],7,0),"") | N37: ObjectID_uid | P37: from s_createrkoext t1 left join s_createrkoextresult t2 on t2.createrkoext_short_foreign_key=t1.objectID left join s_party t3 on t3.createrkoext_short_foreign_key=t1.objectID left join s_optionalparam t4 on t4.createrkoext_short_foreign_key=t1.objectID left join s_depart t5 on t2.createrkoext_short_foreign_key=t1.objectID where t1.inc_flag=1 or t2.inc_flag=1 or t3.inc_flag=1 or t4.inc_flag=1 or t5.inc_flag=1 Источник для всех полей этого блока - S таблицы выше | Q37: ="n306000041_"&IFERROR(VLOOKUP(D37,target_tables[],5,0),"<not found>") -> n306000041_appl | R37: Ключ | S37: Снимок-снимок | T37: Сорокин М. Б. | U37: 45370
A38: 460 | D38: t_appl | E38: =IFERROR(VLOOKUP($D38&$J38,target_columns[],4,0),"") -> uuid | F38: =IFERROR(VLOOKUP($D38&$J38,target_columns[],7,0),"") -> No | G38: =IFERROR(VLOOKUP($D38&$J38,target_columns[],8,0),"") -> Yes | H38: =IFERROR(VLOOKUP($D38&$J38,target_columns[],5,0),"") -> NULL | I38: =IFERROR(VLOOKUP($D38&$J38,target_columns[],10,0),"") -> Тип заявки | J38: appl_type_id | K38: b3060000410002_createrkoext | L38: =IFERROR(VLOOKUP(UPPER(K38&N38),source_columns[],4,0),"") | M38: =IFERROR(VLOOKUP(UPPER(K38&N38),source_columns[],7,0),"") | N38: operationType_uid | Q38: ="n306000041_"&IFERROR(VLOOKUP(D38,target_tables[],5,0),"<not found>") -> n306000041_appl | R38: - | T38: Сорокин М. Б. | U38: 45370
A39: 470 | D39: t_appl | E39: =IFERROR(VLOOKUP($D39&$J39,target_columns[],4,0),"") -> uuid | F39: =IFERROR(VLOOKUP($D39&$J39,target_columns[],7,0),"") -> No | G39: =IFERROR(VLOOKUP($D39&$J39,target_columns[],8,0),"") -> Yes | H39: =IFERROR(VLOOKUP($D39&$J39,target_columns[],5,0),"") -> NULL | I39: =IFERROR(VLOOKUP($D39&$J39,target_columns[],10,0),"") -> Система-источник заявки | J39: src_system_type_id | K39: b3060000410002_createrkoext | L39: =IFERROR(VLOOKUP(UPPER(K39&N39),source_columns[],4,0),"") | M39: =IFERROR(VLOOKUP(UPPER(K39&N39),source_columns[],7,0),"") | N39: spName_uid | Q39: ="n306000041_"&IFERROR(VLOOKUP(D39,target_tables[],5,0),"<not found>") -> n306000041_appl | R39: - | T39: Сорокин М. Б. | U39: 45370
A40: 471 | D40: t_appl | E40: =IFERROR(VLOOKUP($D40&$J40,target_columns[],4,0),"") -> text | F40: =IFERROR(VLOOKUP($D40&$J40,target_columns[],7,0),"") -> No | G40: =IFERROR(VLOOKUP($D40&$J40,target_columns[],8,0),"") -> No | H40: =IFERROR(VLOOKUP($D40&$J40,target_columns[],5,0),"") -> NULL | I40: =IFERROR(VLOOKUP($D40&$J40,target_columns[],10,0),"") -> Текст ошибки | J40: error_txt | K40: b3060000410002_createrkoext | L40: =IFERROR(VLOOKUP(UPPER(K40&N40),source_columns[],4,0),"") | M40: =IFERROR(VLOOKUP(UPPER(K40&N40),source_columns[],7,0),"") | N40: errcode | Q40: ="n306000041_"&IFERROR(VLOOKUP(D40,target_tables[],5,0),"<not found>") -> n306000041_appl | R40: - | T40: Сорокин М. Б. | U40: 45370
A41: 472 | D41: t_appl | E41: =IFERROR(VLOOKUP($D41&$J41,target_columns[],4,0),"") -> text | F41: =IFERROR(VLOOKUP($D41&$J41,target_columns[],7,0),"") -> No | G41: =IFERROR(VLOOKUP($D41&$J41,target_columns[],8,0),"") -> No | H41: =IFERROR(VLOOKUP($D41&$J41,target_columns[],5,0),"") -> NULL | I41: =IFERROR(VLOOKUP($D41&$J41,target_columns[],10,0),"") -> Номер договора ДБО | J41: agr_dbo_num | K41: b3060000410014_optionalParam | L41: =IFERROR(VLOOKUP(UPPER(K41&N41),source_columns[],4,0),"") | M41: =IFERROR(VLOOKUP(UPPER(K41&N41),source_columns[],7,0),"") | N41: sbbolnumdog | Q41: ="n306000041_"&IFERROR(VLOOKUP(D41,target_tables[],5,0),"<not found>") -> n306000041_appl | R41: - | T41: Сорокин М. Б. | U41: 45370
...

Sheet Source columns
D1: =COLUMN() -> 4 | E1: =COLUMN() -> 5 | F1: =COLUMN() -> 6 | G1: =COLUMN() -> 7 | I1: Проверка соответствия типов S2T
A2: Seek | B2: Название таблицы STAGE | C2: Название поля | D2: Тип поля | E2: Первичный ключ | F2: NULL? | G2: Описание поля | H2: Описание таблицы | I2: Seek | J2: Тип поля | K2: Результат
A3: =source_columns[[#This Row],[Название таблицы STAGE]]&source_columns[[#This Row],[Название поля]] -> b3060000410001_registerObjectID | B3: b3060000410001_register | C3: ObjectID | D3: bigint | E3: Yes | F3: NOT NULL | G3: Уникальный идентификатор | H3: Регистры | K3: =IF(I3="","",IF(ISNA(VLOOKUP(I3,$A$3:$D$117,4,FALSE)),"Ошибка. Seek не найден",IF(VLOOKUP(I3,$A$3:$D$117,4,FALSE)=J3,"ОК","Ошибка. Тип данных в S2T: "&VLOOKUP(I3,$A$3:$D$117,4,FALSE))))
A4: =source_columns[[#This Row],[Название таблицы STAGE]]&source_columns[[#This Row],[Название поля]] -> b3060000410001_registerbeginDate | B4: b3060000410001_register | C4: beginDate | D4: timestamp | E4: No | F4: NULL | G4: Дата открытия | K4: =IF(I4="","",IF(ISNA(VLOOKUP(I4,$A$3:$D$117,4,FALSE)),"Ошибка. Seek не найден",IF(VLOOKUP(I4,$A$3:$D$117,4,FALSE)=J4,"ОК","Ошибка. Тип данных в S2T: "&VLOOKUP(I4,$A$3:$D$117,4,FALSE))))
A5: =source_columns[[#This Row],[Название таблицы STAGE]]&source_columns[[#This Row],[Название поля]] -> b3060000410001_registerendDate | B5: b3060000410001_register | C5: endDate | D5: timestamp | E5: No | F5: NULL | G5: Дата закрытия | K5: =IF(I5="","",IF(ISNA(VLOOKUP(I5,$A$3:$D$117,4,FALSE)),"Ошибка. Seek не найден",IF(VLOOKUP(I5,$A$3:$D$117,4,FALSE)=J5,"ОК","Ошибка. Тип данных в S2T: "&VLOOKUP(I5,$A$3:$D$117,4,FALSE))))
A6: =source_columns[[#This Row],[Название таблицы STAGE]]&source_columns[[#This Row],[Название поля]] -> b3060000410001_registercurrency_short_foreign_key_uid | B6: b3060000410001_register | C6: currency_short_foreign_key_uid | D6: uuid | E6: No | F6: NULL | G6: Валюта | K6: =IF(I6="","",IF(ISNA(VLOOKUP(I6,$A$3:$D$117,4,FALSE)),"Ошибка. Seek не найден",IF(VLOOKUP(I6,$A$3:$D$117,4,FALSE)=J6,"ОК","Ошибка. Тип данных в S2T: "&VLOOKUP(I6,$A$3:$D$117,4,FALSE))))
A7: =source_columns[[#This Row],[Название таблицы STAGE]]&source_columns[[#This Row],[Название поля]] -> b3060000410001_registercurrency_short_foreign_key | B7: b3060000410001_register | C7: currency_short_foreign_key | D7: text | E7: No | F7: NULL | G7: Валюта | K7: =IF(I7="","",IF(ISNA(VLOOKUP(I7,$A$3:$D$117,4,FALSE)),"Ошибка. Seek не найден",IF(VLOOKUP(I7,$A$3:$D$117,4,FALSE)=J7,"ОК","Ошибка. Тип данных в S2T: "&VLOOKUP(I7,$A$3:$D$117,4,FALSE))))
A8: =source_columns[[#This Row],[Название таблицы STAGE]]&source_columns[[#This Row],[Название поля]] -> b3060000410001_registernumber | B8: b3060000410001_register | C8: number | D8: text | E8: No | F8: NULL | G8: Номер счета | K8: =IF(I8="","",IF(ISNA(VLOOKUP(I8,$A$3:$D$117,4,FALSE)),"Ошибка. Seek не найден",IF(VLOOKUP(I8,$A$3:$D$117,4,FALSE)=J8,"ОК","Ошибка. Тип данных в S2T: "&VLOOKUP(I8,$A$3:$D$117,4,FALSE))))
A9: =source_columns[[#This Row],[Название таблицы STAGE]]&source_columns[[#This Row],[Название поля]] -> b3060000410001_registerObjectID_uid | B9: b3060000410001_register | C9: ObjectID_uid | D9: uuid | E9: No | F9: NULL | K9: =IF(I9="","",IF(ISNA(VLOOKUP(I9,$A$3:$D$117,4,FALSE)),"Ошибка. Seek не найден",IF(VLOOKUP(I9,$A$3:$D$117,4,FALSE)=J9,"ОК","Ошибка. Тип данных в S2T: "&VLOOKUP(I9,$A$3:$D$117,4,FALSE))))
A10: =source_columns[[#This Row],[Название таблицы STAGE]]&source_columns[[#This Row],[Название поля]] -> b3060000410001_registerproduct_short_foreign_key | B10: b3060000410001_register | C10: product_short_foreign_key | D10: bigint | E10: No | F10: NULL | G10: Договор | K10: =IF(I10="","",IF(ISNA(VLOOKUP(I10,$A$3:$D$117,4,FALSE)),"Ошибка. Seek не найден",IF(VLOOKUP(I10,$A$3:$D$117,4,FALSE)=J10,"ОК","Ошибка. Тип данных в S2T: "&VLOOKUP(I10,$A$3:$D$117,4,FALSE))))
A11: =source_columns[[#This Row],[Название таблицы STAGE]]&source_columns[[#This Row],[Название поля]] -> b3060000410001_registerproduct_short_foreign_key_uid | B11: b3060000410001_register | C11: product_short_foreign_key_uid | D11: uuid | E11: No | F11: NULL | G11: Договор | K11: =IF(I11="","",IF(ISNA(VLOOKUP(I11,$A$3:$D$117,4,FALSE)),"Ошибка. Seek не найден",IF(VLOOKUP(I11,$A$3:$D$117,4,FALSE)=J11,"ОК","Ошибка. Тип данных в S2T: "&VLOOKUP(I11,$A$3:$D$117,4,FALSE))))
A12: =source_columns[[#This Row],[Название таблицы STAGE]]&source_columns[[#This Row],[Название поля]] -> b3060000410001_registerregisterType_short_foreign_key | B12: b3060000410001_register | C12: registerType_short_foreign_key | D12: text | E12: No | F12: NULL | G12: Тип регистра | K12: =IF(I12="","",IF(ISNA(VLOOKUP(I12,$A$3:$D$117,4,FALSE)),"Ошибка. Seek не найден",IF(VLOOKUP(I12,$A$3:$D$117,4,FALSE)=J12,"ОК","Ошибка. Тип данных в S2T: "&VLOOKUP(I12,$A$3:$D$117,4,FALSE))))
A13: =source_columns[[#This Row],[Название таблицы STAGE]]&source_columns[[#This Row],[Название поля]] -> b3060000410001_registerstatus_short_foreign_key_uid | B13: b3060000410001_register | C13: status_short_foreign_key_uid | D13: uuid | E13: No | F13: NULL | G13: Статус регистра
A14: =source_columns[[#This Row],[Название таблицы STAGE]]&source_columns[[#This Row],[Название поля]] -> b3060000410001_registerregisterType_short_foreign_key_uid | B14: b3060000410001_register | C14: registerType_short_foreign_key_uid | D14: uuid | E14: No | F14: NULL | G14: Тип регистра | K14: =IF(I14="","",IF(ISNA(VLOOKUP(I14,$A$3:$D$117,4,FALSE)),"Ошибка. Seek не найден",IF(VLOOKUP(I14,$A$3:$D$117,4,FALSE)=J14,"ОК","Ошибка. Тип данных в S2T: "&VLOOKUP(I14,$A$3:$D$117,4,FALSE))))
A15: =source_columns[[#This Row],[Название таблицы STAGE]]&source_columns[[#This Row],[Название поля]] -> b3060000410001_registerstatus_short_foreign_key | B15: b3060000410001_register | C15: status_short_foreign_key | D15: text | E15: No | F15: NULL | G15: Статус регистра
A16: =source_columns[[#This Row],[Название таблицы STAGE]]&source_columns[[#This Row],[Название поля]] -> b3060000410002_createrkoextObjectID | B16: b3060000410002_createrkoext | C16: ObjectID | D16: bigint | E16: Yes | F16: NOT NULL | G16: Уникальный идентификатор | H16: Заявки на РКО
A17: =source_columns[[#This Row],[Название таблицы STAGE]]&source_columns[[#This Row],[Название поля]] -> b3060000410002_createrkoexterrCode | B17: b3060000410002_createrkoext | C17: errCode | D17: text | E17: No | F17: NULL | G17: Код ошибки | K17: =IF(I17="","",IF(ISNA(VLOOKUP(I17,$A$3:$D$117,4,FALSE)),"Ошибка. Seek не найден",IF(VLOOKUP(I17,$A$3:$D$117,4,FALSE)=J17,"ОК","Ошибка. Тип данных в S2T: "&VLOOKUP(I17,$A$3:$D$117,4,FALSE))))
A18: =source_columns[[#This Row],[Название таблицы STAGE]]&source_columns[[#This Row],[Название поля]] -> b3060000410002_createrkoextchannel | B18: b3060000410002_createrkoext | C18: channel | D18: text | E18: No | F18: NULL | G18: Наименование канала | K18: =IF(I18="","",IF(ISNA(VLOOKUP(I18,$A$3:$D$117,4,FALSE)),"Ошибка. Seek не найден",IF(VLOOKUP(I18,$A$3:$D$117,4,FALSE)=J18,"ОК","Ошибка. Тип данных в S2T: "&VLOOKUP(I18,$A$3:$D$117,4,FALSE))))
A19: =source_columns[[#This Row],[Название таблицы STAGE]]&source_columns[[#This Row],[Название поля]] -> b3060000410002_createrkoextchannel_uid | B19: b3060000410002_createrkoext | C19: channel_uid | D19: uuid | E19: No | F19: NULL | G19: Наименование канала | K19: =IF(I19="","",IF(ISNA(VLOOKUP(I19,$A$3:$D$117,4,FALSE)),"Ошибка. Seek не найден",IF(VLOOKUP(I19,$A$3:$D$117,4,FALSE)=J19,"ОК","Ошибка. Тип данных в S2T: "&VLOOKUP(I19,$A$3:$D$117,4,FALSE))))
A20: =source_columns[[#This Row],[Название таблицы STAGE]]&source_columns[[#This Row],[Название поля]] -> b3060000410002_createrkoextcreatedProduct_entityId | B20: b3060000410002_createrkoext | C20: createdProduct_entityId | D20: bigint | E20: No | F20: NULL | G20: Договор | K20: =IF(I20="","",IF(ISNA(VLOOKUP(I20,$A$3:$D$117,4,FALSE)),"Ошибка. Seek не найден",IF(VLOOKUP(I20,$A$3:$D$117,4,FALSE)=J20,"ОК","Ошибка. Тип данных в S2T: "&VLOOKUP(I20,$A$3:$D$117,4,FALSE))))
A21: =source_columns[[#This Row],[Название таблицы STAGE]]&source_columns[[#This Row],[Название поля]] -> b3060000410002_createrkoextoperationType_uid | B21: b3060000410002_createrkoext | C21: operationType_uid | D21: uuid | E21: No | F21: NULL | G21: Тип операции | K21: =IF(I21="","",IF(ISNA(VLOOKUP(I21,$A$3:$D$117,4,FALSE)),"Ошибка. Seek не найден",IF(VLOOKUP(I21,$A$3:$D$117,4,FALSE)=J21,"ОК","Ошибка. Тип данных в S2T: "&VLOOKUP(I21,$A$3:$D$117,4,FALSE))))
A22: =source_columns[[#This Row],[Название таблицы STAGE]]&source_columns[[#This Row],[Название поля]] -> b3060000410002_createrkoextrqtm | B22: b3060000410002_createrkoext | C22: rqtm | D22: timestamp | E22: No | F22: NULL | G22: Дата заявки | K22: =IF(I22="","",IF(ISNA(VLOOKUP(I22,$A$3:$D$117,4,FALSE)),"Ошибка. Seek не найден",IF(VLOOKUP(I22,$A$3:$D$117,4,FALSE)=J22,"ОК","Ошибка. Тип данных в S2T: "&VLOOKUP(I22,$A$3:$D$117,4,FALSE))))
A23: =source_columns[[#This Row],[Название таблицы STAGE]]&source_columns[[#This Row],[Название поля]] -> b3060000410002_createrkoextstatusForRko_short_foreign_key | B23: b3060000410002_createrkoext | C23: statusForRko_short_foreign_key | D23: bigint | E23: No | F23: NULL | G23: Статус заявки | K23: =IF(I23="","",IF(ISNA(VLOOKUP(I23,$A$3:$D$117,4,FALSE)),"Ошибка. Seek не найден",IF(VLOOKUP(I23,$A$3:$D$117,4,FALSE)=J23,"ОК","Ошибка. Тип данных в S2T: "&VLOOKUP(I23,$A$3:$D$117,4,FALSE))))
A24: =source_columns[[#This Row],[Название таблицы STAGE]]&source_columns[[#This Row],[Название поля]] -> b3060000410002_createrkoextstatusForRko_short_foreign_key_uid | B24: b3060000410002_createrkoext | C24: statusForRko_short_foreign_key_uid | D24: uuid | E24: No | F24: NULL | G24: Статус заявки | K24: =IF(I24="","",IF(ISNA(VLOOKUP(I24,$A$3:$D$117,4,FALSE)),"Ошибка. Seek не найден",IF(VLOOKUP(I24,$A$3:$D$117,4,FALSE)=J24,"ОК","Ошибка. Тип данных в S2T: "&VLOOKUP(I24,$A$3:$D$117,4,FALSE))))
A25: =source_columns[[#This Row],[Название таблицы STAGE]]&source_columns[[#This Row],[Название поля]] -> b3060000410002_createrkoextoperationType | B25: b3060000410002_createrkoext | C25: operationType | D25: text | E25: No | F25: NULL | G25: Тип операции | K25: =IF(I25="","",IF(ISNA(VLOOKUP(I25,$A$3:$D$117,4,FALSE)),"Ошибка. Seek не найден",IF(VLOOKUP(I25,$A$3:$D$117,4,FALSE)=J25,"ОК","Ошибка. Тип данных в S2T: "&VLOOKUP(I25,$A$3:$D$117,4,FALSE))))
A26: =source_columns[[#This Row],[Название таблицы STAGE]]&source_columns[[#This Row],[Название поля]] -> b3060000410002_createrkoextspName_uid | B26: b3060000410002_createrkoext | C26: spName_uid | D26: uuid | E26: No | F26: NULL | G26: Идентификатор системы, которая сформировала сообщение | K26: =IF(I26="","",IF(ISNA(VLOOKUP(I26,$A$3:$D$117,4,FALSE)),"Ошибка. Seek не найден",IF(VLOOKUP(I26,$A$3:$D$117,4,FALSE)=J26,"ОК","Ошибка. Тип данных в S2T: "&VLOOKUP(I26,$A$3:$D$117,4,FALSE))))
A27: =source_columns[[#This Row],[Название таблицы STAGE]]&source_columns[[#This Row],[Название поля]] -> b3060000410002_createrkoextspName | B27: b3060000410002_createrkoext | C27: spName | D27: text | E27: No | F27: NULL | G27: Идентификатор системы, которая сформировала сообщение | K27: =IF(I27="","",IF(ISNA(VLOOKUP(I27,$A$3:$D$117,4,FALSE)),"Ошибка. Seek не найден",IF(VLOOKUP(I27,$A$3:$D$117,4,FALSE)=J27,"ОК","Ошибка. Тип данных в S2T: "&VLOOKUP(I27,$A$3:$D$117,4,FALSE))))
A28: =source_columns[[#This Row],[Название таблицы STAGE]]&source_columns[[#This Row],[Название поля]] -> b3060000410002_createrkoextObjectID_uid | B28: b3060000410002_createrkoext | C28: ObjectID_uid | D28: uuid | E28: No | F28: NULL
A29: =source_columns[[#This Row],[Название таблицы STAGE]]&source_columns[[#This Row],[Название поля]] -> b3060000410003_partyObjectID | B29: b3060000410003_party | C29: ObjectID | D29: bigint | E29: Yes | F29: NOT NULL | G29: Уникальный идентификатор | H29: Клиенты
A30: =source_columns[[#This Row],[Название таблицы STAGE]]&source_columns[[#This Row],[Название поля]] -> b3060000410003_partyepkID | B30: b3060000410003_party | C30: epkID | D30: bigint | E30: No | F30: NULL | G30: ID карточки клиента (Организации/ИП) в ЕПК | K30: =IF(I30="","",IF(ISNA(VLOOKUP(I30,$A$3:$D$117,4,FALSE)),"Ошибка. Seek не найден",IF(VLOOKUP(I30,$A$3:$D$117,4,FALSE)=J30,"ОК","Ошибка. Тип данных в S2T: "&VLOOKUP(I30,$A$3:$D$117,4,FALSE))))
A31: =source_columns[[#This Row],[Название таблицы STAGE]]&source_columns[[#This Row],[Название поля]] -> b3060000410003_partyepkID_uuid | B31: b3060000410003_party | C31: epkID_uuid | D31: uuid | E31: No | F31: NULL | G31: ID карточки клиента (Организации/ИП) в ЕПК | K31: =IF(I31="","",IF(ISNA(VLOOKUP(I31,$A$3:$D$117,4,FALSE)),"Ошибка. Seek не найден",IF(VLOOKUP(I31,$A$3:$D$117,4,FALSE)=J31,"ОК","Ошибка. Тип данных в S2T: "&VLOOKUP(I31,$A$3:$D$117,4,FALSE))))
A32: =source_columns[[#This Row],[Название таблицы STAGE]]&source_columns[[#This Row],[Название поля]] -> b3060000410003_partycreateRkoExt_short_foreign_key | B32: b3060000410003_party | C32: createRkoExt_short_foreign_key | D32: bigint | E32: No | F32: NULL | G32: ID заявки | K32: =IF(I32="","",IF(ISNA(VLOOKUP(I32,$A$3:$D$117,4,FALSE)),"Ошибка. Seek не найден",IF(VLOOKUP(I32,$A$3:$D$117,4,FALSE)=J32,"ОК","Ошибка. Тип данных в S2T: "&VLOOKUP(I32,$A$3:$D$117,4,FALSE))))
A33: =source_columns[[#This Row],[Название таблицы STAGE]]&source_columns[[#This Row],[Название поля]] -> b3060000410003_partycreateRkoExt_short_foreign_key_uid | B33: b3060000410003_party | C33: createRkoExt_short_foreign_key_uid | D33: uuid | E33: No | F33: NULL | G33: ID заявки | K33: =IF(I33="","",IF(ISNA(VLOOKUP(I33,$A$3:$D$117,4,FALSE)),"Ошибка. Seek не найден",IF(VLOOKUP(I33,$A$3:$D$117,4,FALSE)=J33,"ОК","Ошибка. Тип данных в S2T: "&VLOOKUP(I33,$A$3:$D$117,4,FALSE))))
A34: =source_columns[[#This Row],[Название таблицы STAGE]]&source_columns[[#This Row],[Название поля]] -> b3060000410004_productObjectID | B34: b3060000410004_product | C34: ObjectID | D34: bigint | E34: Yes | F34: NOT NULL | G34: Уникальный идентификатор | H34: Договоры РКО | K34: =IF(I34="","",IF(ISNA(VLOOKUP(I34,$A$3:$D$117,4,FALSE)),"Ошибка. Seek не найден",IF(VLOOKUP(I34,$A$3:$D$117,4,FALSE)=J34,"ОК","Ошибка. Тип данных в S2T: "&VLOOKUP(I34,$A$3:$D$117,4,FALSE))))
A35: =source_columns[[#This Row],[Название таблицы STAGE]]&source_columns[[#This Row],[Название поля]] -> b3060000410004_productbeginDate | B35: b3060000410004_product | C35: beginDate | D35: timestamp | E35: No | F35: NULL | G35: Дата открытия | K35: =IF(I35="","",IF(ISNA(VLOOKUP(I35,$A$3:$D$117,4,FALSE)),"Ошибка. Seek не найден",IF(VLOOKUP(I35,$A$3:$D$117,4,FALSE)=J35,"ОК","Ошибка. Тип данных в S2T: "&VLOOKUP(I35,$A$3:$D$117,4,FALSE))))
A36: =source_columns[[#This Row],[Название таблицы STAGE]]&source_columns[[#This Row],[Название поля]] -> b3060000410004_productcloseDate | B36: b3060000410004_product | C36: closeDate | D36: timestamp | E36: No | F36: NULL | G36: Дата закрытия | K36: =IF(I36="","",IF(ISNA(VLOOKUP(I36,$A$3:$D$117,4,FALSE)),"Ошибка. Seek не найден",IF(VLOOKUP(I36,$A$3:$D$117,4,FALSE)=J36,"ОК","Ошибка. Тип данных в S2T: "&VLOOKUP(I36,$A$3:$D$117,4,FALSE))))
A37: =source_columns[[#This Row],[Название таблицы STAGE]]&source_columns[[#This Row],[Название поля]] -> b3060000410004_productcurrency_short_foreign_key | B37: b3060000410004_product | C37: currency_short_foreign_key | D37: text | E37: No | F37: NULL | G37: Валюта договора РКО | K37: =IF(I37="","",IF(ISNA(VLOOKUP(I37,$A$3:$D$117,4,FALSE)),"Ошибка. Seek не найден",IF(VLOOKUP(I37,$A$3:$D$117,4,FALSE)=J37,"ОК","Ошибка. Тип данных в S2T: "&VLOOKUP(I37,$A$3:$D$117,4,FALSE))))
A38: =source_columns[[#This Row],[Название таблицы STAGE]]&source_columns[[#This Row],[Название поля]] -> b3060000410004_productcurrency_short_foreign_key_uid | B38: b3060000410004_product | C38: currency_short_foreign_key_uid | D38: uuid | E38: No | F38: NULL | G38: Валюта договора РКО | K38: =IF(I38="","",IF(ISNA(VLOOKUP(I38,$A$3:$D$117,4,FALSE)),"Ошибка. Seek не найден",IF(VLOOKUP(I38,$A$3:$D$117,4,FALSE)=J38,"ОК","Ошибка. Тип данных в S2T: "&VLOOKUP(I38,$A$3:$D$117,4,FALSE))))
A39: =source_columns[[#This Row],[Название таблицы STAGE]]&source_columns[[#This Row],[Название поля]] -> b3060000410004_productdivisionId | B39: b3060000410004_product | C39: divisionId | D39: text | E39: No | F39: NULL | G39: Подразделение договора
A40: =source_columns[[#This Row],[Название таблицы STAGE]]&source_columns[[#This Row],[Название поля]] -> b3060000410004_productdivisionId_uid | B40: b3060000410004_product | C40: divisionId_uid | D40: uuid | E40: No | F40: NULL | G40: Подразделение договора
...

Sheet Target tables
D1: =COLUMN() -> 4 | E1: =COLUMN() -> 5
A2: Table Name | B2: Table Entity Definition | C2: Table Entity Note | D2: Table Is In Subject Area Name | E2: Суффикс N-таблицы
A3: t_agr_rko | B3: Договор РКО | E3: agr_rko
A4: t_agr_rko_cust | B4: Клиент договора РКО | E4: agr_rko_cust
A5: t_agr_rko_stts | B5: Статус договора РКО | E5: agr_rko_stts
A6: t_agr_rko_int_org | B6: Подразделение договора РКО | E6: agr_rko_int_org
A7: t_registry | B7: Регистр | E7: registry
A8: t_crncy | B8: Валюта | E8: crncy
A9: t_registry_type | B9: Тип регистра | E9: registry_type
A10: t_int_org | B10: Подразделения СБ РФ | E10: int_org
A11: T_REGISTRY_STTS | B11: Статус регистра | E11: REGISTRY_STTS
A12: t_appl | B12: Заявка на РКО | E12: appl
A13: t_appl_stts | B13: Статус заявки | E13: appl_stts
A14: t_arg_rko_limit | B14: Ограничения на РКО | E14: agr_rko_limit
... A24: t_agr_rko_idfn | B24: Идентификационные характеристики договора | E24: agr_rko_idfn

Sheet Target columns
D1: =COLUMN() -> 4 | E1: =COLUMN() -> 5 | F1: =COLUMN() -> 6 | G1: =COLUMN() -> 7 | H1: =COLUMN() -> 8 | I1: =COLUMN() -> 9 | J1: =COLUMN() -> 10 | K1: Проверка соответствия типов S2T
A2: Seek | B2: Column Table Name | C2: ColumnName | D2: Column Datatype | E2: Column Null Option | F2: Column Physical Only | G2: Column Is PK | H2: Column Is FK | I2: Column Attribute Definition | J2: Column Attribute Note | K2: Seek | L2: Тип поля | M2: Результат
A3: =target_columns[[#This Row],[Column Table Name]]&target_columns[[#This Row],[ColumnName]] -> t_agr_rkoopen_dt | B3: t_agr_rko | C3: open_dt | D3: date | E3: NULL | G3: No | H3: No | J3: Дата открытия | M3: =IF(K3 = "", "", IF(ISNA(VLOOKUP(K3,$A$3:$D$56,4,FALSE)), "Данное поле не внесено в S2T", IF(VLOOKUP(K3,$A$3:$D$56,4,FALSE) = L3, "ОК", "Ошибка. Тип данных в S2T: " & VLOOKUP(K3,$A$3:$D$56,4,FALSE)) ) )
A4: =target_columns[[#This Row],[Column Table Name]]&target_columns[[#This Row],[ColumnName]] -> t_agr_rkoclose_dt | B4: t_agr_rko | C4: close_dt | D4: date | E4: NULL | G4: No | H4: No | J4: Дата закрытия | M4: =IF(K4 = "", "", IF(ISNA(VLOOKUP(K4,$A$3:$D$56,4,FALSE)), "Данное поле не внесено в S2T", IF(VLOOKUP(K4,$A$3:$D$56,4,FALSE) = L4, "ОК", "Ошибка. Тип данных в S2T: " & VLOOKUP(K4,$A$3:$D$56,4,FALSE)) ) )
A5: =target_columns[[#This Row],[Column Table Name]]&target_columns[[#This Row],[ColumnName]] -> t_agr_rkoagr_rko_num | B5: t_agr_rko | C5: agr_rko_num | D5: text | E5: NULL | G5: No | H5: No | J5: Номер договора | M5: =IF(K5 = "", "", IF(ISNA(VLOOKUP(K5,$A$3:$D$56,4,FALSE)), "Данное поле не внесено в S2T", IF(VLOOKUP(K5,$A$3:$D$56,4,FALSE) = L5, "ОК", "Ошибка. Тип данных в S2T: " & VLOOKUP(K5,$A$3:$D$56,4,FALSE)) ) )
A6: =target_columns[[#This Row],[Column Table Name]]&target_columns[[#This Row],[ColumnName]] -> t_agr_rkohost_agr_rko_id | B6: t_agr_rko | C6: host_agr_rko_id | D6: bigint | E6: NULL | G6: No | H6: No | J6: Уникальный идентификатор договора в системе-источнике | M6: =IF(K6 = "", "", IF(ISNA(VLOOKUP(K6,$A$3:$D$56,4,FALSE)), "Данное поле не внесено в S2T", IF(VLOOKUP(K6,$A$3:$D$56,4,FALSE) = L6, "ОК", "Ошибка. Тип данных в S2T: " & VLOOKUP(K6,$A$3:$D$56,4,FALSE)) ) )
A7: =B7&C7 -> t_agr_rkocrncy_id | B7: t_agr_rko | C7: crncy_id | D7: uuid | E7: NULL | G7: No | H7: Yes | J7: Валюта договора
A8: =target_columns[[#This Row],[Column Table Name]]&target_columns[[#This Row],[ColumnName]] -> t_agr_rkorko_purpose_type_id | B8: t_agr_rko | C8: rko_purpose_type_id | D8: uuid | E8: NULL | G8: No | H8: Yes | J8: Целевое назначение договора (счета) | M8: =IF(K8 = "", "", IF(ISNA(VLOOKUP(K8,$A$3:$D$56,4,FALSE)), "Данное поле не внесено в S2T", IF(VLOOKUP(K8,$A$3:$D$56,4,FALSE) = L8, "ОК", "Ошибка. Тип данных в S2T: " & VLOOKUP(K8,$A$3:$D$56,4,FALSE)) ) )
A9: =target_columns[[#This Row],[Column Table Name]]&target_columns[[#This Row],[ColumnName]] -> t_agr_rkoagr_rko_id | B9: t_agr_rko | C9: agr_rko_id | D9: uuid | E9: NOT NULL | G9: Yes | H9: No | J9: Уникальный идентификатор договора | M9: =IF(K9 = "", "", IF(ISNA(VLOOKUP(K9,$A$3:$D$56,4,FALSE)), "Данное поле не внесено в S2T", IF(VLOOKUP(K9,$A$3:$D$56,4,FALSE) = L9, "ОК", "Ошибка. Тип данных в S2T: " & VLOOKUP(K9,$A$3:$D$56,4,FALSE)) ) )
A10: =target_columns[[#This Row],[Column Table Name]]&target_columns[[#This Row],[ColumnName]] -> t_agr_rko_custagr_rko_id | B10: t_agr_rko_cust | C10: agr_rko_id | D10: uuid | E10: NOT NULL | G10: Yes | H10: Yes | J10: Уникальный идентификатор договора | M10: =IF(K10 = "", "", IF(ISNA(VLOOKUP(K10,$A$3:$D$56,4,FALSE)), "Данное поле не внесено в S2T", IF(VLOOKUP(K10,$A$3:$D$56,4,FALSE) = L10, "ОК", "Ошибка. Тип данных в S2T: " & VLOOKUP(K10,$A$3:$D$56,4,FALSE)) ) )
A11: =target_columns[[#This Row],[Column Table Name]]&target_columns[[#This Row],[ColumnName]] -> t_agr_rko_custstart_dt | B11: t_agr_rko_cust | C11: start_dt | D11: date | E11: NULL | G11: Yes | H11: No | J11: Дата начала действия связи | M11: =IF(K11 = "", "", IF(ISNA(VLOOKUP(K11,$A$3:$D$56,4,FALSE)), "Данное поле не внесено в S2T", IF(VLOOKUP(K11,$A$3:$D$56,4,FALSE) = L11, "ОК", "Ошибка. Тип данных в S2T: " & VLOOKUP(K11,$A$3:$D$56,4,FALSE)) ) )
A12: =target_columns[[#This Row],[Column Table Name]]&target_columns[[#This Row],[ColumnName]] -> t_agr_rko_custend_dt | B12: t_agr_rko_cust | C12: end_dt | D12: date | E12: NULL | G12: No | H12: No | J12: Дата окончания действия связи | M12: =IF(K12 = "", "", IF(ISNA(VLOOKUP(K12,$A$3:$D$56,4,FALSE)), "Данное поле не внесено в S2T", IF(VLOOKUP(K12,$A$3:$D$56,4,FALSE) = L12, "ОК", "Ошибка. Тип данных в S2T: " & VLOOKUP(K12,$A$3:$D$56,4,FALSE)) ) )
A13: =target_columns[[#This Row],[Column Table Name]]&target_columns[[#This Row],[ColumnName]] -> t_agr_rko_custcust_id | B13: t_agr_rko_cust | C13: cust_id | D13: uuid | E13: NULL | G13: No | H13: Yes | J13: Клиент по договору | M13: =IF(K13 = "", "", IF(ISNA(VLOOKUP(K13,$A$3:$D$56,4,FALSE)), "Данное поле не внесено в S2T", IF(VLOOKUP(K13,$A$3:$D$56,4,FALSE) = L13, "ОК", "Ошибка. Тип данных в S2T: " & VLOOKUP(K13,$A$3:$D$56,4,FALSE)) ) )
A14: =target_columns[[#This Row],[Column Table Name]]&target_columns[[#This Row],[ColumnName]] -> t_agr_rko_int_orgagr_rko_id | B14: t_agr_rko_int_org | C14: agr_rko_id | D14: uuid | E14: NOT NULL | G14: Yes | H14: Yes | J14: Уникальный идентификатор договора | M14: =IF(K14 = "", "", IF(ISNA(VLOOKUP(K14,$A$3:$D$56,4,FALSE)), "Данное поле не внесено в S2T", IF(VLOOKUP(K14,$A$3:$D$56,4,FALSE) = L14, "ОК", "Ошибка. Тип данных в S2T: " & VLOOKUP(K14,$A$3:$D$56,4,FALSE)) ) )
A15: =target_columns[[#This Row],[Column Table Name]]&target_columns[[#This Row],[ColumnName]] -> t_agr_rko_int_orgstart_dt | B15: t_agr_rko_int_org | C15: start_dt | D15: date | E15: NULL | G15: Yes | H15: No | J15: Дата начала действия связи | M15: =IF(K15 = "", "", IF(ISNA(VLOOKUP(K15,$A$3:$D$56,4,FALSE)), "Данное поле не внесено в S2T", IF(VLOOKUP(K15,$A$3:$D$56,4,FALSE) = L15, "ОК", "Ошибка. Тип данных в S2T: " & VLOOKUP(K15,$A$3:$D$56,4,FALSE)) ) )
A16: =target_columns[[#This Row],[Column Table Name]]&target_columns[[#This Row],[ColumnName]] -> t_agr_rko_int_orgend_dt | B16: t_agr_rko_int_org | C16: end_dt | D16: date | E16: NULL | G16: No | H16: No | J16: Дата окончания действия связи | M16: =IF(K16 = "", "", IF(ISNA(VLOOKUP(K16,$A$3:$D$56,4,FALSE)), "Данное поле не внесено в S2T", IF(VLOOKUP(K16,$A$3:$D$56,4,FALSE) = L16, "ОК", "Ошибка. Тип данных в S2T: " & VLOOKUP(K16,$A$3:$D$56,4,FALSE)) ) )
A17: =target_columns[[#This Row],[Column Table Name]]&target_columns[[#This Row],[ColumnName]] -> t_agr_rko_int_orgint_org_id | B17: t_agr_rko_int_org | C17: int_org_id | D17: uuid | E17: NULL | G17: No | H17: Yes | J17: Подразделение сопровождения договора | M17: =IF(K17 = "", "", IF(ISNA(VLOOKUP(K17,$A$3:$D$56,4,FALSE)), "Данное поле не внесено в S2T", IF(VLOOKUP(K17,$A$3:$D$56,4,FALSE) = L17, "ОК", "Ошибка. Тип данных в S2T: " & VLOOKUP(K17,$A$3:$D$56,4,FALSE)) ) )
A18: =target_columns[[#This Row],[Column Table Name]]&target_columns[[#This Row],[ColumnName]] -> t_agr_rko_sttsagr_rko_id | B18: t_agr_rko_stts | C18: agr_rko_id | D18: uuid | E18: NOT NULL | G18: Yes | H18: Yes | J18: Уникальный идентификатор договора | M18: =IF(K18 = "", "", IF(ISNA(VLOOKUP(K18,$A$3:$D$56,4,FALSE)), "Данное поле не внесено в S2T", IF(VLOOKUP(K18,$A$3:$D$56,4,FALSE) = L18, "ОК", "Ошибка. Тип данных в S2T: " & VLOOKUP(K18,$A$3:$D$56,4,FALSE)) ) )
A19: =target_columns[[#This Row],[Column Table Name]]&target_columns[[#This Row],[ColumnName]] -> t_agr_rko_sttsstart_dt | B19: t_agr_rko_stts | C19: start_dt | D19: date | E19: NULL | G19: Yes | H19: No | J19: Дата начала действия связи | M19: =IF(K19 = "", "", IF(ISNA(VLOOKUP(K19,$A$3:$D$56,4,FALSE)), "Данное поле не внесено в S2T", IF(VLOOKUP(K19,$A$3:$D$56,4,FALSE) = L19, "ОК", "Ошибка. Тип данных в S2T: " & VLOOKUP(K19,$A$3:$D$56,4,FALSE)) ) )
... A22: =target_columns[[#This Row],[Column Table Name]]&target_columns[[#This Row],[ColumnName]] -> t_registryregistry_id | B22: t_registry | C22: registry_id | D22: uuid | E22: NOT NULL | G22: Yes | H22: No | J22: Уникальный идентификатор регистра | M22: =IF(K22 = "", "", IF(ISNA(VLOOKUP(K22,$A$3:$D$56,4,FALSE)), "Данное поле не внесено в S2T", IF(VLOOKUP(K22,$A$3:$D$56,4,FALSE) = L22, "ОК", "Ошибка. Тип данных в S2T: " & VLOOKUP(K22,$A$3:$D$56,4,FALSE)) ) )
A23: =B23&C23 -> t_registrystart_dt | B23: t_registry | C23: start_dt | D23: date | E23: NULL | G23: No | H23: No | J23: Дата опердня, в которую был открыт регистр
A24: =B24&C24 -> t_registryend_dt | B24: t_registry | C24: end_dt | D24: date | E24: NULL | G24: No | H24: No | J24: Дата опердня, в которую был закрыт регистр
A25: =B25&C25 -> t_registrycoa_num | B25: t_registry | C25: coa_num | D25: text | E25: NULL | G25: No | H25: No | J25: Лицевой счет
A26: =B26&C26 -> t_registrycrncy_id | B26: t_registry | C26: crncy_id | D26: uuid | E26: NULL | G26: No | H26: No | J26: Уникальный идентификатор валюты
A27: =target_columns[[#This Row],[Column Table Name]]&target_columns[[#This Row],[ColumnName]] -> t_registryagr_id | B27: t_registry | C27: agr_id | D27: uuid | E27: NULL | G27: No | H27: Yes | J27: Договор | M27: =IF(K27 = "", "", IF(ISNA(VLOOKUP(K27,$A$3:$D$56,4,FALSE)), "Данное поле не внесено в S2T", IF(VLOOKUP(K27,$A$3:$D$56,4,FALSE) = L27, "ОК", "Ошибка. Тип данных в S2T: " & VLOOKUP(K27,$A$3:$D$56,4,FALSE)) ) )
A28: =target_columns[[#This Row],[Column Table Name]]&target_columns[[#This Row],[ColumnName]] -> t_registryregistry_type_id | B28: t_registry | C28: registry_type_id | D28: uuid | E28: NULL | G28: No | H28: Yes | J28: Тип регистра | M28: =IF(K28 = "", "", IF(ISNA(VLOOKUP(K28,$A$3:$D$56,4,FALSE)), "Данное поле не внесено в S2T", IF(VLOOKUP(K28,$A$3:$D$56,4,FALSE) = L28, "ОК", "Ошибка. Тип данных в S2T: " & VLOOKUP(K28,$A$3:$D$56,4,FALSE)) ) )
